Workbook

Sheet README
A1: Parish Finder data
A3: How to use this workbook
A4: 1. Parishes sheet: one row per parish or church. parish_id is permanent; never change or reuse it. New parish: next free number for its diocese (e.g. BLR-131).
A5: 2. Masses sheet: one row per service. Link it to a parish with parish_id. A Mass on 7 days is 7 rows. Use 24-hour time (18:30).
A6: 3. Dropdowns (day, type, geo_status, active) come from the Lists sheet. Add a language to Lists and it appears in the dropdown.
A7: 4. Location: every pin is "approximate" until someone checks it. Click map_link to open the pin in Google Maps; if the church is elsewhere, right-click it in Google Maps, copy the coordinates into latitude/longitude, and set geo_status to "verified".
A8: 5. geo_precision says how the pin was found: post_office = the post office named in the address (usually within 1-2 km); pincode = the main post office of that pincode (can be several km off in rural areas); locality = matched by place name only. Check pincode and locality pins first.
A9: 6. For exact church pins from Google, run: python geocode.py parish_data.xlsx --google YOUR_API_KEY (it never touches "verified" rows).
A10: 7. When done, run: python build_json.py parish_data.xlsx parishes.json
A12: Field notes
A13: phone: Bangalore 8-digit landlines were given the 080- STD code so tap-to-call works.
A14: Masses: only Chikmagalur has timings so far, parsed from the diocese website text. They default to recurrence "Weekly" and blank language. Please review these, especially language.
... A17: Source: List_of_Parishes.xlsx (Master Parish List + diocese directory sheets), migrated 2026-10-29.

Sheet Parishes
A1: parish_id | B1: name | C1: patron | D1: diocese | E1: diocese_code | F1: rite | G1: deanery | H1: address | I1: locality | J1: city | K1: district | L1: state | M1: pincode | N1: latitude | O1: longitude | P1: geo_status | Q1: geo_precision | R1: map_link | S1: phone | T1: email | U1: website | V1: languages | W1: year_established | X1: catholics | Y1: feast_day
A2: BLR-001 | B2: St Mary's Minor Basilica Church | D2: Archdiocese of Bangalore | E2: LAT-BANGALORE | F2: Latin | H2: Msgr. F. Noronha Road, Shivajinagar, Bengaluru 560 051 | I2: Shivajinagar | J2: Bengaluru | L2: Karnataka | M2: 560051 | N2: 12.155389 | O2: 78.011806 | P2: approximate | Q2: pincode | R2: =IF(N2="","",HYPERLINK("https://www.google.com/maps/search/?api=1&query="&N2&","&O2,"Check pin")) -> Check pin | S2: 080-22865434; 080-22868627 | U2: https://www.stmarysbasilica.in | W2: 1702
A3: BLR-002 | B3: Infant Jesus Church and Shrine | D3: Archdiocese of Bangalore | E3: LAT-BANGALORE | F3: Latin | H3: Post Box 4712, Viveknagar, Bengaluru 560 047 | I3: Viveknagar | J3: Bengaluru | L3: Karnataka | M3: 560047 | N3: 12.944722 | O3: 77.574028 | P3: approximate | Q3: post_office | R3: =IF(N3="","",HYPERLINK("https://www.google.com/maps/search/?api=1&query="&N3&","&O3,"Check pin")) -> Check pin | S3: 080-25301206 | W3: 1971
A4: BLR-003 | B4: St Francis Xavier Cathedral | D4: Archdiocese of Bangalore | E4: LAT-BANGALORE | F4: Latin | H4: Promenade Road, Post Box No. 584, Father Servanton Circle, Cleveland Town, Bengaluru 560 005 | I4: Cleveland Town | J4: Bengaluru | L4: Karnataka | M4: 560005 | N4: 13.000722 | O4: 77.616139 | P4: approximate | Q4: pincode | R4: =IF(N4="","",HYPERLINK("https://www.google.com/maps/search/?api=1&query="&N4&","&O4,"Check pin")) -> Check pin | S4: 080-25542563
A5: BLR-004 | B5: Holy Ghost Parish | D5: Archdiocese of Bangalore | E5: LAT-BANGALORE | F5: Latin | H5: No. 9/1, Clarke Road, Richard's Town, Bengaluru 560 084 | I5: Richard's Town | J5: Bengaluru | L5: Karnataka | M5: 560084 | N5: 13.013389 | O5: 77.62975 | P5: approximate | Q5: pincode | R5: =IF(N5="","",HYPERLINK("https://www.google.com/maps/search/?api=1&query="&N5&","&O5,"Check pin")) -> Check pin | S5: 080-25470499; 080-25465493 | U5: https://www.holyghostchurch.in | W5: 1953
A6: BLR-005 | B6: Our Lady of Lourdes Church | D6: Archdiocese of Bangalore | E6: LAT-BANGALORE | F6: Latin | H6: Whitefield, Bengaluru 560 066 | I6: Whitefield | J6: Bengaluru | L6: Karnataka | M6: 560066 | N6: 12.967713 | O6: 77.749443 | P6: approximate | Q6: post_office | R6: =IF(N6="","",HYPERLINK("https://www.google.com/maps/search/?api=1&query="&N6&","&O6,"Check pin")) -> Check pin | S6: 080-28452231 | U6: https://www.lourdeschurchwhitefield.co.in | W6: 1936
A7: BLR-006 | B7: Sacred Heart Church | D7: Archdiocese of Bangalore | E7: LAT-BANGALORE | F7: Latin | H7: No. 62, Richmond Road, Msgr. D'Souza Circle, Bengaluru 560 025 | I7: Msgr. D'Souza Circle | J7: Bengaluru | L7: Karnataka | M7: 560025 | N7: 12.16325 | O7: 78.013417 | P7: approximate | Q7: post_office | R7: =IF(N7="","",HYPERLINK("https://www.google.com/maps/search/?api=1&query="&N7&","&O7,"Check pin")) -> Check pin | S7: 080-25511955; 080-48651427 | W7: 1874
A8: BLR-007 | B8: Immaculate Conception Church | D8: Archdiocese of Bangalore | E8: LAT-BANGALORE | F8: Latin | H8: Doresanipalya, Bannerghatta Road, I.I.M.B. Post, Bengaluru 560 076 | I8: I.I.M.B. | J8: Bengaluru | L8: Karnataka | M8: 560076 | N8: 12.89865 | O8: 77.601028 | P8: approximate | Q8: post_office | R8: =IF(N8="","",HYPERLINK("https://www.google.com/maps/search/?api=1&query="&N8&","&O8,"Check pin")) -> Check pin | W8: 1928
A9: BLR-008 | B9: Immaculate Heart of Mary Church | D9: Archdiocese of Bangalore | E9: LAT-BANGALORE | F9: Latin | H9: Mt St Joseph's Campus, Kalena Agrahara, IIMB Post, Bannerghatta Road, Bengaluru 560 076 | I9: IIMB | J9: Bengaluru | L9: Karnataka | M9: 560076 | N9: 12.89865 | O9: 77.601028 | P9: approximate | Q9: post_office | R9: =IF(N9="","",HYPERLINK("https://www.google.com/maps/search/?api=1&query="&N9&","&O9,"Check pin")) -> Check pin | T9: immaculateheartchurch76@gmail.com | U9: https://www.kalenaagaraharachurch.com | W9: 2002
A10: BLR-009 | B10: Our Lady of Sacred Heart Church | D10: Archdiocese of Bangalore | E10: LAT-BANGALORE | F10: Latin | H10: Haralur Road, Bellandur Gate, HSR Layout Post, Chevalier Bhavan, Bengaluru 560 102 | I10: Chevalier Bhavan | J10: Bengaluru | L10: Karnataka | M10: 560102 | N10: 12.91411 | O10: 77.637152 | P10: approximate | Q10: post_office | R10: =IF(N10="","",HYPERLINK("https://www.google.com/maps/search/?api=1&query="&N10&","&O10,"Check pin")) -> Check pin | S10: 080-28439750 | T10: parishpriest@olschurch.in | U10: https://www.olshchurch.in | W10: 2000
A11: BLR-010 | B11: Resurrection Church | D11: Archdiocese of Bangalore | E11: LAT-BANGALORE | F11: Latin | H11: Old Madras Road, 80 Ft. Road, Opp. Swami Vivekananda Metro Station, Indiranagar, Bengaluru 560 038 | I11: Indiranagar | J11: Bengaluru | L11: Karnataka | M11: 560038 | N11: 12.944722 | O11: 77.574028 | P11: approximate | Q11: post_office | R11: =IF(N11="","",HYPERLINK("https://www.google.com/maps/search/?api=1&query="&N11&","&O11,"Check pin")) -> Check pin | S11: 080-25284037; 080-25281357 | W11: 1980
A12: BLR-011 | B12: St Anthony's Church | D12: Archdiocese of Bangalore | E12: LAT-BANGALORE | F12: Latin | H12: T. C. Palya, K. R. Puram, Bengaluru 560 036 | I12: K. R. Puram | J12: Bengaluru | L12: Karnataka | M12: 560036 | N12: 13.005167 | O12: 77.696 | P12: approximate | Q12: pincode | R12: =IF(N12="","",HYPERLINK("https://www.google.com/maps/search/?api=1&query="&N12&","&O12,"Check pin")) -> Check pin | S12: 080-28474717 | W12: 1907
A13: BLR-012 | B13: St Anthony's Friary Church | D13: Archdiocese of Bangalore | E13: LAT-BANGALORE | F13: Latin | H13: No. 85, Hosur Road, Madiwala, Koramangala Post, Bengaluru 560 095 | I13: Koramangala | J13: Bengaluru | L13: Karnataka | M13: 560095 | N13: 12.938454 | O13: 77.619149 | P13: approximate | Q13: post_office | R13: =IF(N13="","",HYPERLINK("https://www.google.com/maps/search/?api=1&query="&N13&","&O13,"Check pin")) -> Check pin | S13: 080-25539985 | U13: https://www.friaryparish.com | W13: 1953
A14: BLR-013 | B14: St Francis De Sales Church | D14: Archdiocese of Bangalore | E14: LAT-BANGALORE | F14: Latin | H14: Mermier Nagara, Hebbagodi, Electronic City Post, Bengaluru 560 100 | I14: Electronic City | J14: Bengaluru | L14: Karnataka | M14: 560100 | N14: 12.84007 | O14: 77.663545 | P14: approximate | Q14: post_office | R14: =IF(N14="","",HYPERLINK("https://www.google.com/maps/search/?api=1&query="&N14&","&O14,"Check pin")) -> Check pin | S14: 080-27832825 | U14: https://www.fransalians.com | W14: 1983
A15: BLR-014 | B15: St John The Evangelist Church | D15: Archdiocese of Bangalore | E15: LAT-BANGALORE | F15: Latin | H15: Church Road, J. C. Nagar, Benson Town Post, Bengaluru 560 046 | I15: Benson Town | J15: Bengaluru | L15: Karnataka | M15: 560046 | P15: pending | R15: =IF(N15="","",HYPERLINK("https://www.google.com/maps/search/?api=1&query="&N15&","&O15,"Check pin")) | S15: 080-23333317 | U15: https://www.saintjohntheevangelistchurch.org | W15: 1978
A16: BLR-015 | B16: St Peter's Church | D16: Archdiocese of Bangalore | E16: LAT-BANGALORE | F16: Latin | H16: Rustum Bagh (Behind Manipal Hospital), Old Airport Road, Bengaluru 560 017 | I16: Rustum Bagh (Behind Manipal Hospital) | J16: Bengaluru | L16: Karnataka | M16: 560017 | N16: 12.944722 | O16: 77.574028 | P16: approximate | Q16: pincode | R16: =IF(N16="","",HYPERLINK("https://www.google.com/maps/search/?api=1&query="&N16&","&O16,"Check pin")) -> Check pin | S16: 080-25264343; 080-48516069 | W16: 2002
A17: BLR-016 | B17: Ascension Church | D17: Archdiocese of Bangalore | E17: LAT-BANGALORE | F17: Latin | H17: 2nd Cross, Da'Costa Layout, St Mary's Town Post, Bengaluru 560 084 | I17: St Mary's Town | J17: Bengaluru | L17: Karnataka | M17: 560084 | N17: 13.013389 | O17: 77.62975 | P17: approximate | Q17: pincode | R17: =IF(N17="","",HYPERLINK("https://www.google.com/maps/search/?api=1&query="&N17&","&O17,"Check pin")) -> Check pin | T17: ascensionchurchaccts@gmail.com | W17: 1968
A18: BLR-017 | B18: Christha Prabhalaya Epiphany Church | D18: Archdiocese of Bangalore | E18: LAT-BANGALORE | F18: Latin | H18: 16th Main, 4th Block East, Jayanagar, Bengaluru 560 011 | I18: Jayanagar | J18: Bengaluru | L18: Karnataka | M18: 560011 | N18: 12.930504 | O18: 77.58354 | P18: approximate | Q18: pincode | R18: =IF(N18="","",HYPERLINK("https://www.google.com/maps/search/?api=1&query="&N18&","&O18,"Check pin")) -> Check pin | S18: 080-26630361 | W18: 1968
A19: BLR-018 | B19: Don Bosco Church | D19: Archdiocese of Bangalore | E19: LAT-BANGALORE | F19: Latin | H19: No. 5/10, Don Bosco Street, Lingarajapuram, St. Thomas Town P.O., Bengaluru 560 084 | I19: St. Thomas Town | J19: Bengaluru | L19: Karnataka | M19: 560084 | N19: 13.013389 | O19: 77.62975 | P19: approximate | Q19: post_office | R19: =IF(N19="","",HYPERLINK("https://www.google.com/maps/search/?api=1&query="&N19&","&O19,"Check pin")) -> Check pin | S19: 080-25488694 | W19: 1995
A20: BLR-019 | B20: Holy Family Church | D20: Archdiocese of Bangalore | E20: LAT-BANGALORE | F20: Latin | H20: Ramamurthy Nagar Main Road, Dooravaninagar Post, Bengaluru 560 016 | I20: Dooravaninagar | J20: Bengaluru | L20: Karnataka | M20: 560016 | N20: 13.014083 | O20: 77.68275 | P20: approximate | Q20: post_office | R20: =IF(N20="","",HYPERLINK("https://www.google.com/maps/search/?api=1&query="&N20&","&O20,"Check pin")) -> Check pin | S20: 080-25650571 | W20: 1969
A21: BLR-020 | B21: Holy Redeemer Church | D21: Archdiocese of Bangalore | E21: LAT-BANGALORE | F21: Latin | H21: Sadupadesha Vidyalaya, 28/1, Hennuru Bande Main Road, Bengaluru 560 043 | I21: Sadupadesha Vidyalaya | J21: Bengaluru | L21: Karnataka | M21: 560043 | N21: 12.944722 | O21: 77.574028 | P21: approximate | Q21: pincode | R21: =IF(N21="","",HYPERLINK("https://www.google.com/maps/search/?api=1&query="&N21&","&O21,"Check pin")) -> Check pin | W21: 2010
A22: BLR-021 | B22: Immaculate Conception Church | D22: Archdiocese of Bangalore | E22: LAT-BANGALORE | F22: Latin | H22: M.G. Railway Colony, Bengaluru 560 023 | I22: M.G. Railway Colony | J22: Bengaluru | L22: Karnataka | M22: 560023 | N22: 12.975571 | O22: 77.560338 | P22: approximate | Q22: pincode | R22: =IF(N22="","",HYPERLINK("https://www.google.com/maps/search/?api=1&query="&N22&","&O22,"Check pin")) -> Check pin | S22: 080-23150168; 080-23109387 | W22: 1901
A23: BLR-022 | B23: Our Lady of Fatima Church | D23: Archdiocese of Bangalore | E23: LAT-BANGALORE | F23: Latin | H23: Jalahalli, H.M.T. Post, Bengaluru 560 013 | I23: H.M.T. | J23: Bengaluru | L23: Karnataka | M23: 560013 | N23: 13.064257 | O23: 77.546488 | P23: approximate | Q23: post_office | R23: =IF(N23="","",HYPERLINK("https://www.google.com/maps/search/?api=1&query="&N23&","&O23,"Check pin")) -> Check pin | S23: 080-28389631 | W23: 1953
A24: BLR-023 | B24: Our Lady of Lourdes Church | D24: Archdiocese of Bangalore | E24: LAT-BANGALORE | F24: Latin | H24: Lourdunagara, Virgonagara Post, Bengaluru 560 049 | I24: Virgonagara | J24: Bengaluru | L24: Karnataka | M24: 560049 | N24: 13.018417 | O24: 77.718417 | P24: approximate | Q24: post_office | R24: =IF(N24="","",HYPERLINK("https://www.google.com/maps/search/?api=1&query="&N24&","&O24,"Check pin")) -> Check pin | W24: 1983
A25: BLR-024 | B25: St Paul Church | D25: Archdiocese of Bangalore | E25: LAT-BANGALORE | F25: Latin | H25: 8th Mile, Chokkasandra, Nagasandra Post, Bengaluru 560 073 | I25: Nagasandra | J25: Bengaluru | L25: Karnataka | M25: 560073 | N25: 13.056573 | O25: 77.508083 | P25: approximate | Q25: post_office | R25: =IF(N25="","",HYPERLINK("https://www.google.com/maps/search/?api=1&query="&N25&","&O25,"Check pin")) -> Check pin | T25: stpaulchurchblr@gmail.com | W25: 1997
A26: BLR-025 | B26: St Pius X Church | D26: Archdiocese of Bangalore | E26: LAT-BANGALORE | F26: Latin | H26: Kammanahalli, St Thomas Town Post, Bengaluru 560 084 | I26: St Thomas Town | J26: Bengaluru | L26: Karnataka | M26: 560084 | N26: 13.013389 | O26: 77.62975 | P26: approximate | Q26: post_office | R26: =IF(N26="","",HYPERLINK("https://www.google.com/maps/search/?api=1&query="&N26&","&O26,"Check pin")) -> Check pin | S26: 080-25456994 | W26: 1965
A27: BLR-026 | B27: Christ the King Church | D27: Archdiocese of Bangalore | E27: LAT-BANGALORE | F27: Latin | H27: 8th Main Road, Malleswaram West, Bengaluru 560 055 | I27: Malleswaram West | J27: Bengaluru | L27: Karnataka | M27: 560055 | N27: 13.009049 | O27: 77.562867 | P27: approximate | Q27: post_office | R27: =IF(N27="","",HYPERLINK("https://www.google.com/maps/search/?api=1&query="&N27&","&O27,"Check pin")) -> Check pin | S27: 080-23342313 | W27: 1947
A28: BLR-027 | B28: Good Shepherd Church | D28: Archdiocese of Bangalore | E28: LAT-BANGALORE | F28: Latin | H28: Thamarai Kannan Road, Hoysalanagar, Murphy Town, Halasuru Post, Bengaluru 560 008 | I28: Halasuru | J28: Bengaluru | L28: Karnataka | M28: 560008 | N28: 12.968488 | O28: 77.642574 | P28: approximate | Q28: pincode | R28: =IF(N28="","",HYPERLINK("https://www.google.com/maps/search/?api=1&query="&N28&","&O28,"Check pin")) -> Check pin | S28: 080-25300498 | U28: https://www.goodshepherd.co.in | W28: 1967
A29: BLR-028 | B29: Holy Rosary Church | D29: Archdiocese of Bangalore | E29: LAT-BANGALORE | F29: Latin | H29: New Airport Road, Venkatala, Yelahanka Post, Bengaluru 560 064 | I29: Yelahanka | J29: Bengaluru | L29: Karnataka | M29: 560064 | N29: 13.085278 | O29: 77.568806 | P29: approximate | Q29: post_office | R29: =IF(N29="","",HYPERLINK("https://www.google.com/maps/search/?api=1&query="&N29&","&O29,"Check pin")) -> Check pin | S29: 080-28571164 | U29: https://www.holyrosarychurchbangalore.com | W29: 1970
A30: BLR-029 | B30: Mother of Mines Shrine | D30: Archdiocese of Bangalore | E30: LAT-BANGALORE | F30: Latin | H30: Orgaum Post, K.G.F. 563 120 | I30: K.G.F | L30: Karnataka | M30: 563120 | N30: 12.9565 | O30: 78.237667 | P30: approximate | Q30: post_office | R30: =IF(N30="","",HYPERLINK("https://www.google.com/maps/search/?api=1&query="&N30&","&O30,"Check pin")) -> Check pin | S30: 08153-260513 | W30: 1975
A31: BLR-030 | B31: Nativity Church | D31: Archdiocese of Bangalore | E31: LAT-BANGALORE | F31: Latin | H31: No. 431, AMS Layout, Vidyaranyapura, II Phase, Bengaluru 560 097 | I31: II Phase | J31: Bengaluru | L31: Karnataka | M31: 560097 | N31: 13.079368 | O31: 77.559539 | P31: approximate | Q31: post_office | R31: =IF(N31="","",HYPERLINK("https://www.google.com/maps/search/?api=1&query="&N31&","&O31,"Check pin")) -> Check pin | S31: 080-23641910 | T31: nativitychurchvidyaranyapura@hotmail.com | U31: https://www.nativityparish.in | W31: 1999
A32: BLR-031 | B32: Our Lady of Lourdes Church | D32: Archdiocese of Bangalore | E32: LAT-BANGALORE | F32: Latin | H32: No. 14, Cambridge Road, Halasuru, Bengaluru 560 008 | I32: Halasuru | J32: Bengaluru | L32: Karnataka | M32: 560008 | N32: 12.165583 | O32: 77.106778 | P32: approximate | Q32: post_office | R32: =IF(N32="","",HYPERLINK("https://www.google.com/maps/search/?api=1&query="&N32&","&O32,"Check pin")) -> Check pin | S32: 080-25306855 | W32: 1937
A33: BLR-032 | B33: Our Lady of Mount Carmel Church | D33: Archdiocese of Bangalore | E33: LAT-BANGALORE | F33: Latin | H33: Mariapura, Thattuguppe Post, Via Udayapura, Bengaluru 560 082 | I33: Via Udayapura | J33: Bengaluru | L33: Karnataka | M33: 560082 | N33: 12.823298 | O33: 77.514065 | P33: approximate | Q33: post_office | R33: =IF(N33="","",HYPERLINK("https://www.google.com/maps/search/?api=1&query="&N33&","&O33,"Check pin")) -> Check pin | W33: 1905
A34: BLR-033 | B34: Our Lady of Victories Church | D34: Archdiocese of Bangalore | E34: LAT-BANGALORE | F34: Latin | H34: Champion Reefs, K.G.F. 563 117 | I34: K.G.F | L34: Karnataka | M34: 563117 | N34: 12.936417 | O34: 78.261361 | P34: approximate | Q34: post_office | R34: =IF(N34="","",HYPERLINK("https://www.google.com/maps/search/?api=1&query="&N34&","&O34,"Check pin")) -> Check pin | S34: 08153 - 274507 | U34: https://www.victorieschurchkgf.com | W34: 1899
A35: BLR-034 | B35: Sacred Heart Church | D35: Archdiocese of Bangalore | E35: LAT-BANGALORE | F35: Latin | H35: Siluvepura, Tharabanahalli Post, Bengaluru 560 090 | I35: Tharabanahalli | J35: Bengaluru | L35: Karnataka | M35: 560090 | N35: 13.086295 | O35: 77.497311 | P35: approximate | Q35: post_office | R35: =IF(N35="","",HYPERLINK("https://www.google.com/maps/search/?api=1&query="&N35&","&O35,"Check pin")) -> Check pin | S35: 080-28466055 | W35: 1880
A36: BLR-035 | B36: Ss Peter and Paul Church | D36: Archdiocese of Bangalore | E36: LAT-BANGALORE | F36: Latin | H36: Jagajivan Ram Nagara, Rayapuram, Bengaluru 560 018 | I36: Rayapuram | J36: Bengaluru | L36: Karnataka | M36: 560018 | N36: 12.956167 | O36: 77.566106 | P36: approximate | Q36: pincode | R36: =IF(N36="","",HYPERLINK("https://www.google.com/maps/search/?api=1&query="&N36&","&O36,"Check pin")) -> Check pin | U36: https://www.sspeterandpaulchurch.in | W36: 1951
A37: BLR-036 | B37: St Anthony's Church | D37: Archdiocese of Bangalore | E37: LAT-BANGALORE | F37: Latin | H37: St. Anthony's Church Street, Off Sarjapura Main Road, Kodathi, Carmelaram Post, Bengaluru 560 035 | I37: Carmelaram | J37: Bengaluru | L37: Karnataka | M37: 560035 | N37: 12.907512 | O37: 77.695678 | P37: approximate | Q37: post_office | R37: =IF(N37="","",HYPERLINK("https://www.google.com/maps/search/?api=1&query="&N37&","&O37,"Check pin")) -> Check pin | W37: 1884
A38: BLR-037 | B38: St Ignatius Church | D38: Archdiocese of Bangalore | E38: LAT-BANGALORE | F38: Latin | H38: Begur, Bengaluru 560 114 | I38: Begur | J38: Bengaluru | L38: Karnataka | M38: 560114 | N38: 12.870465 | O38: 77.626906 | P38: approximate | Q38: post_office | R38: =IF(N38="","",HYPERLINK("https://www.google.com/maps/search/?api=1&query="&N38&","&O38,"Check pin")) -> Check pin | S38: 080-25730884 | W38: 1860
A39: BLR-038 | B39: St Ignatius Church | D39: Archdiocese of Bangalore | E39: LAT-BANGALORE | F39: Latin | H39: Beguru, Bengaluru 560 114 | I39: Beguru | J39: Bengaluru | L39: Karnataka | M39: 560114 | N39: 12.870465 | O39: 77.626906 | P39: approximate | Q39: post_office | R39: =IF(N39="","",HYPERLINK("https://www.google.com/maps/search/?api=1&query="&N39&","&O39,"Check pin")) -> Check pin | S39: 080-25730884 | W39: 1860
A40: BLR-039 | B40: St James Church | D40: Archdiocese of Bangalore | E40: LAT-BANGALORE | F40: Latin | H40: Mariannapalya, Hebbal Agricultural Farm Post, Bengaluru 560 024 | I40: Hebbal Agricultural Farm | J40: Bengaluru | L40: Karnataka | M40: 560024 | N40: 13.030435 | O40: 77.586664 | P40: approximate | Q40: pincode | R40: =IF(N40="","",HYPERLINK("https://www.google.com/maps/search/?api=1&query="&N40&","&O40,"Check pin")) -> Check pin | S40: 080-22330384 | W40: 1943
...

Sheet Masses
A1: mass_id | B1: parish_id | C1: parish_name | D1: day | E1: time | F1: type | G1: language | H1: venue | I1: recurrence | J1: notes
A2: CKM-001-M01 | B2: CKM-001 | C2: =IF(B2="","",IFERROR(INDEX(Parishes!$B:$B,MATCH(B2,Parishes!$A:$A,0)),"⚠ unknown parish_id")) -> St. Alphonsus Church | D2: Monday | E2: 06:00 | F2: Adoration | I2: Weekly
A3: CKM-001-M02 | B3: CKM-001 | C3: =IF(B3="","",IFERROR(INDEX(Parishes!$B:$B,MATCH(B3,Parishes!$A:$A,0)),"⚠ unknown parish_id")) -> St. Alphonsus Church | D3: Monday | E3: 06:30 | F3: Mass | I3: Weekly
A4: CKM-001-M03 | B4: CKM-001 | C4: =IF(B4="","",IFERROR(INDEX(Parishes!$B:$B,MATCH(B4,Parishes!$A:$A,0)),"⚠ unknown parish_id")) -> St. Alphonsus Church | D4: Tuesday | E4: 06:00 | F4: Adoration | I4: Weekly
A5: CKM-001-M04 | B5: CKM-001 | C5: =IF(B5="","",IFERROR(INDEX(Parishes!$B:$B,MATCH(B5,Parishes!$A:$A,0)),"⚠ unknown parish_id")) -> St. Alphonsus Church | D5: Tuesday | E5: 06:30 | F5: Mass | I5: Weekly
A6: CKM-001-M05 | B6: CKM-001 | C6: =IF(B6="","",IFERROR(INDEX(Parishes!$B:$B,MATCH(B6,Parishes!$A:$A,0)),"⚠ unknown parish_id")) -> St. Alphonsus Church | D6: Wednesday | E6: 06:00 | F6: Adoration | I6: Weekly
A7: CKM-001-M06 | B7: CKM-001 | C7: =IF(B7="","",IFERROR(INDEX(Parishes!$B:$B,MATCH(B7,Parishes!$A:$A,0)),"⚠ unknown parish_id")) -> St. Alphonsus Church | D7: Wednesday | E7: 06:30 | F7: Mass | I7: Weekly
A8: CKM-001-M07 | B8: CKM-001 | C8: =IF(B8="","",IFERROR(INDEX(Parishes!$B:$B,MATCH(B8,Parishes!$A:$A,0)),"⚠ unknown parish_id")) -> St. Alphonsus Church | D8: Thursday | E8: 06:00 | F8: Adoration | I8: Weekly
A9: CKM-001-M08 | B9: CKM-001 | C9: =IF(B9="","",IFERROR(INDEX(Parishes!$B:$B,MATCH(B9,Parishes!$A:$A,0)),"⚠ unknown parish_id")) -> St. Alphonsus Church | D9: Thursday | E9: 06:30 | F9: Mass | I9: Weekly
A10: CKM-001-M09 | B10: CKM-001 | C10: =IF(B10="","",IFERROR(INDEX(Parishes!$B:$B,MATCH(B10,Parishes!$A:$A,0)),"⚠ unknown parish_id")) -> St. Alphonsus Church | D10: Friday | E10: 18:00 | F10: Mass | I10: Weekly | J10: adoration and Mass
A11: CKM-001-M10 | B11: CKM-001 | C11: =IF(B11="","",IFERROR(INDEX(Parishes!$B:$B,MATCH(B11,Parishes!$A:$A,0)),"⚠ unknown parish_id")) -> St. Alphonsus Church | D11: Saturday | E11: 06:00 | F11: Adoration | I11: Weekly
A12: CKM-001-M11 | B12: CKM-001 | C12: =IF(B12="","",IFERROR(INDEX(Parishes!$B:$B,MATCH(B12,Parishes!$A:$A,0)),"⚠ unknown parish_id")) -> St. Alphonsus Church | D12: Saturday | E12: 06:30 | F12: Mass | I12: Weekly
A13: CKM-001-M12 | B13: CKM-001 | C13: =IF(B13="","",IFERROR(INDEX(Parishes!$B:$B,MATCH(B13,Parishes!$A:$A,0)),"⚠ unknown parish_id")) -> St. Alphonsus Church | D13: Sunday | E13: 06:00 | F13: Adoration | I13: Weekly
A14: CKM-001-M13 | B14: CKM-001 | C14: =IF(B14="","",IFERROR(INDEX(Parishes!$B:$B,MATCH(B14,Parishes!$A:$A,0)),"⚠ unknown parish_id")) -> St. Alphonsus Church | D14: Sunday | E14: 06:30 | F14: Mass | I14: Weekly
A15: CKM-001-M14 | B15: CKM-001 | C15: =IF(B15="","",IFERROR(INDEX(Parishes!$B:$B,MATCH(B15,Parishes!$A:$A,0)),"⚠ unknown parish_id")) -> St. Alphonsus Church | D15: Sunday | E15: 09:00 | F15: Mass | H15: Jayangara | I15: Weekly
A16: CKM-002-M01 | B16: CKM-002 | C16: =IF(B16="","",IFERROR(INDEX(Parishes!$B:$B,MATCH(B16,Parishes!$A:$A,0)),"⚠ unknown parish_id")) -> St. John the Evangelist Church | D16: Monday | E16: 06:30 | F16: Mass | H16: Convent | I16: Weekly
A17: CKM-002-M02 | B17: CKM-002 | C17: =IF(B17="","",IFERROR(INDEX(Parishes!$B:$B,MATCH(B17,Parishes!$A:$A,0)),"⚠ unknown parish_id")) -> St. John the Evangelist Church | D17: Tuesday | E17: 17:30 | F17: Mass | I17: Weekly
A18: CKM-002-M03 | B18: CKM-002 | C18: =IF(B18="","",IFERROR(INDEX(Parishes!$B:$B,MATCH(B18,Parishes!$A:$A,0)),"⚠ unknown parish_id")) -> St. John the Evangelist Church | D18: Wednesday | E18: 06:30 | F18: Mass | I18: Weekly
A19: CKM-002-M04 | B19: CKM-002 | C19: =IF(B19="","",IFERROR(INDEX(Parishes!$B:$B,MATCH(B19,Parishes!$A:$A,0)),"⚠ unknown parish_id")) -> St. John the Evangelist Church | D19: Thursday | E19: 06:30 | F19: Mass | I19: Weekly
A20: CKM-002-M05 | B20: CKM-002 | C20: =IF(B20="","",IFERROR(INDEX(Parishes!$B:$B,MATCH(B20,Parishes!$A:$A,0)),"⚠ unknown parish_id")) -> St. John the Evangelist Church | D20: Friday | E20: 05:30 | F20: Mass | I20: Weekly
A21: CKM-002-M06 | B21: CKM-002 | C21: =IF(B21="","",IFERROR(INDEX(Parishes!$B:$B,MATCH(B21,Parishes!$A:$A,0)),"⚠ unknown parish_id")) -> St. John the Evangelist Church | D21: Saturday | E21: 06:30 | F21: Mass | I21: Weekly
A22: CKM-002-M07 | B22: CKM-002 | C22: =IF(B22="","",IFERROR(INDEX(Parishes!$B:$B,MATCH(B22,Parishes!$A:$A,0)),"⚠ unknown parish_id")) -> St. John the Evangelist Church | D22: Saturday | E22: 17:00 | F22: Rosary | I22: Weekly
A23: CKM-002-M08 | B23: CKM-002 | C23: =IF(B23="","",IFERROR(INDEX(Parishes!$B:$B,MATCH(B23,Parishes!$A:$A,0)),"⚠ unknown parish_id")) -> St. John the Evangelist Church | D23: Saturday | E23: 17:30 | F23: Vigil Mass | H23: Hulkodu | I23: Weekly | J23: Mass (Sunday Mass)
A24: CKM-002-M09 | B24: CKM-002 | C24: =IF(B24="","",IFERROR(INDEX(Parishes!$B:$B,MATCH(B24,Parishes!$A:$A,0)),"⚠ unknown parish_id")) -> St. John the Evangelist Church | D24: Sunday | E24: 07:00 | F24: Rosary | I24: Weekly
A25: CKM-002-M10 | B25: CKM-002 | C25: =IF(B25="","",IFERROR(INDEX(Parishes!$B:$B,MATCH(B25,Parishes!$A:$A,0)),"⚠ unknown parish_id")) -> St. John the Evangelist Church | D25: Sunday | E25: 07:30 | F25: Mass | H25: Malasavara | I25: Weekly
A26: CKM-002-M11 | B26: CKM-002 | C26: =IF(B26="","",IFERROR(INDEX(Parishes!$B:$B,MATCH(B26,Parishes!$A:$A,0)),"⚠ unknown parish_id")) -> St. John the Evangelist Church | D26: Sunday | E26: 09:30 | F26: Rosary | I26: Weekly
A27: CKM-002-M12 | B27: CKM-002 | C27: =IF(B27="","",IFERROR(INDEX(Parishes!$B:$B,MATCH(B27,Parishes!$A:$A,0)),"⚠ unknown parish_id")) -> St. John the Evangelist Church | D27: Sunday | E27: 10:00 | F27: Mass | H27: Arehally | I27: Weekly
A28: CKM-002-M13 | B28: CKM-002 | C28: =IF(B28="","",IFERROR(INDEX(Parishes!$B:$B,MATCH(B28,Parishes!$A:$A,0)),"⚠ unknown parish_id")) -> St. John the Evangelist Church | D28: Sunday | E28: 17:00 | F28: Rosary | I28: Weekly
A29: CKM-002-M14 | B29: CKM-002 | C29: =IF(B29="","",IFERROR(INDEX(Parishes!$B:$B,MATCH(B29,Parishes!$A:$A,0)),"⚠ unknown parish_id")) -> St. John the Evangelist Church | D29: Sunday | E29: 17:30 | F29: Mass | H29: Hosamane | I29: Weekly
A30: CKM-003-M01 | B30: CKM-003 | C30: =IF(B30="","",IFERROR(INDEX(Parishes!$B:$B,MATCH(B30,Parishes!$A:$A,0)),"⚠ unknown parish_id")) -> St. Mary’s Church | D30: Monday | E30: 07:00 | F30: Mass | H30: Convent | I30: Weekly
A31: CKM-003-M02 | B31: CKM-003 | C31: =IF(B31="","",IFERROR(INDEX(Parishes!$B:$B,MATCH(B31,Parishes!$A:$A,0)),"⚠ unknown parish_id")) -> St. Mary’s Church | D31: Tuesday | E31: 06:00 | F31: Adoration | I31: Weekly
A32: CKM-003-M03 | B32: CKM-003 | C32: =IF(B32="","",IFERROR(INDEX(Parishes!$B:$B,MATCH(B32,Parishes!$A:$A,0)),"⚠ unknown parish_id")) -> St. Mary’s Church | D32: Tuesday | E32: 06:30 | F32: Mass | I32: Weekly
A33: CKM-003-M04 | B33: CKM-003 | C33: =IF(B33="","",IFERROR(INDEX(Parishes!$B:$B,MATCH(B33,Parishes!$A:$A,0)),"⚠ unknown parish_id")) -> St. Mary’s Church | D33: Wednesday | E33: 07:00 | F33: Mass | H33: Convent | I33: Weekly
A34: CKM-003-M05 | B34: CKM-003 | C34: =IF(B34="","",IFERROR(INDEX(Parishes!$B:$B,MATCH(B34,Parishes!$A:$A,0)),"⚠ unknown parish_id")) -> St. Mary’s Church | D34: Thursday | E34: 06:00 | F34: Adoration | I34: Weekly
A35: CKM-003-M06 | B35: CKM-003 | C35: =IF(B35="","",IFERROR(INDEX(Parishes!$B:$B,MATCH(B35,Parishes!$A:$A,0)),"⚠ unknown parish_id")) -> St. Mary’s Church | D35: Thursday | E35: 06:30 | F35: Mass | I35: Weekly
A36: CKM-003-M07 | B36: CKM-003 | C36: =IF(B36="","",IFERROR(INDEX(Parishes!$B:$B,MATCH(B36,Parishes!$A:$A,0)),"⚠ unknown parish_id")) -> St. Mary’s Church | D36: Friday | E36: 17:00 | F36: Rosary | I36: Weekly
A37: CKM-003-M08 | B37: CKM-003 | C37: =IF(B37="","",IFERROR(INDEX(Parishes!$B:$B,MATCH(B37,Parishes!$A:$A,0)),"⚠ unknown parish_id")) -> St. Mary’s Church | D37: Friday | E37: 17:30 | F37: Mass | I37: Weekly
A38: CKM-003-M09 | B38: CKM-003 | C38: =IF(B38="","",IFERROR(INDEX(Parishes!$B:$B,MATCH(B38,Parishes!$A:$A,0)),"⚠ unknown parish_id")) -> St. Mary’s Church | D38: Saturday | E38: 17:00 | F38: Rosary | I38: Weekly
A39: CKM-003-M10 | B39: CKM-003 | C39: =IF(B39="","",IFERROR(INDEX(Parishes!$B:$B,MATCH(B39,Parishes!$A:$A,0)),"⚠ unknown parish_id")) -> St. Mary’s Church | D39: Saturday | E39: 17:30 | F39: Mass | I39: Weekly
A40: CKM-003-M11 | B40: CKM-003 | C40: =IF(B40="","",IFERROR(INDEX(Parishes!$B:$B,MATCH(B40,Parishes!$A:$A,0)),"⚠ unknown parish_id")) -> St. Mary’s Church | D40: Sunday | E40: 06:00 | F40: Adoration | I40: Weekly
...

Sheet Lists
A1: day | B1: type | C1: language | D1: geo_status | E1: recurrence | F1: geo_precision
A2: Monday | B2: Mass | C2: Kannada | D2: pending | E2: Weekly | F2: exact
A3: Tuesday | B3: Vigil Mass | C3: Konkani | D3: approximate | E3: First Friday | F3: post_office
A4: Wednesday | B4: Adoration | C4: English | D4: verified | E4: First Saturday | F4: pincode
A5: Thursday | B5: Rosary | C5: Tamil | E5: First & Third week | F5: locality
A6: Friday | B6: Novena | C6: Malayalam | E6: Second & Fourth week
A7: Saturday | B7: Confession | C7: Telugu | E7: Seasonal
A8: Sunday | B8: Other | C8: Hindi | E8: Special
C9: Tulu
C10: Latin
